<?xml version="1.0" encoding="utf-8"?>
<!-- =================================================================================== -->
<!-- |    This document was autogenerated by xacro from satellite.xacro                | -->
<!-- |    EDITING THIS FILE BY HAND IS NOT RECOMMENDED                                 | -->
<!-- =================================================================================== -->
<robot name="satellite">
  <material name="blue">
    <color rgba="0 0 0.8 1"/>
  </material>
  <material name="black">
    <color rgba="0 0 0 1"/>
  </material>
  <material name="green">
    <color rgba="0 1 0 1"/>
  </material>
  <material name="white">
    <color rgba="1 1 1 1"/>
  </material>
  <!-- <link name="base_dummy"></link> -->
  <!-- links -->
  <link name="base_link">
    <inertial>
      <mass value="60"/>
      <origin xyz="0 0 0"/>
      <inertia ixx="150.0" ixy="0.0" ixz="0.0" iyy="150.0" iyz="0.0" izz="384.0"/>
    </inertial>
    <!-- <visual>
            <origin rpy="0 0 0" xyz="0 0 0"/>
            <geometry>

                <mesh filename="package://exotica_satellite_dynamics_solver/resources/robots/satellite/satellite_base.dae" scale="1 1 1"/>
            </geometry>
        </visual> -->
    <visual>
      <geometry>
        <box size="2.5 2.5 4"/>
      </geometry>
    </visual>
    <!-- <collision>
            <origin rpy="0 0 0" xyz="0 0 0"/>
            <geometry>
                <mesh filename="package://exotica_satellite_dynamics_solver/resources/robots/quadrotor/quadrotor_base_convex_hull.stl"/>
            </geometry>
        </collision> -->
  </link>
  <!-- <joint name="base_to_dummy" type="fixed">
        <parent link="base_dummy"/>
        <child link="base_link"/>
        <origin xyz="0 0 0"/>
    </joint> -->
  <!-- antenna and communication arrays -->
  <link name="front">
    <visual>
      <geometry>
        <cylinder length="4" radius="1"/>
      </geometry>
      <origin rpy="0 0 0" xyz="0 0 2"/>
      <material name="black"/>
    </visual>
    <inertial>
      <mass value="1e-12"/>
      <origin xyz="0 0 0"/>
      <inertia ixx="1e-12" ixy="0.0" ixz="0.0" iyy="1e-12" iyz="0.0" izz="1e-12"/>
    </inertial>
  </link>
  <link name="left_array">
    <visual>
      <geometry>
        <box size="12 0.2 2"/>
      </geometry>
      <origin rpy="0.785 0 0" xyz="-6 0 0"/>
      <material name="white"/>
    </visual>
    <inertial>
      <mass value="1e-12"/>
      <origin xyz="0 0 0"/>
      <inertia ixx="1e-12" ixy="0.0" ixz="0.0" iyy="1e-12" iyz="0.0" izz="1e-12"/>
    </inertial>
  </link>
  <link name="right_array">
    <visual>
      <geometry>
        <box size="12 0.2 2"/>
      </geometry>
      <origin rpy="0.785 0 0" xyz="6 0 0"/>
      <material name="white"/>
    </visual>
    <inertial>
      <mass value="1e-12"/>
      <origin xyz="0 0 0"/>
      <inertia ixx="1e-12" ixy="0.0" ixz="0.0" iyy="1e-12" iyz="0.0" izz="1e-12"/>
    </inertial>
  </link>
  <link name="top_array">
    <visual>
      <geometry>
        <box size="2 4 0.2"/>
      </geometry>
      <origin rpy="0 0 0" xyz="0 2 0"/>
      <material name="black"/>
    </visual>
    <inertial>
      <mass value="1e-12"/>
      <origin xyz="0 0 0"/>
      <inertia ixx="1e-12" ixy="0.0" ixz="0.0" iyy="1e-12" iyz="0.0" izz="1e-12"/>
    </inertial>
  </link>
  <link name="bot_array">
    <visual>
      <geometry>
        <box size="2 4 0.2"/>
      </geometry>
      <origin rpy="0 0 0" xyz="0 -2 0"/>
      <material name="black"/>
    </visual>
    <inertial>
      <mass value="1e-12"/>
      <origin xyz="0 0 0"/>
      <inertia ixx="1e-12" ixy="0.0" ixz="0.0" iyy="1e-12" iyz="0.0" izz="1e-12"/>
    </inertial>
  </link>
  <link name="thruster_bot">
    <visual>
      <geometry>
        <box size="0.2 0.2 0.2"/>
      </geometry>
      <origin rpy="0 0 0" xyz="0 0 0"/>
      <material name="green"/>
    </visual>
    <inertial>
      <mass value="0.001"/>
      <!-- <origin xyz="0 0 0"/> -->
      <inertia ixx="1e-3" ixy="0.0" ixz="0.0" iyy="1e-3" iyz="0.0" izz="1e-3"/>
    </inertial>
  </link>
  <!-- Prismatic joints with no effort so pinocchio recognizes
            them as controllable joints.
         -->
  <joint name="base_to_thruster_bot" type="fixed">
    <!-- <limit effort="1e-10" lower="0" upper="1e-10" velocity="1e-10"/> -->
    <!-- <axis xyz="${axis}"/> -->
    <!-- <limit effort="1000.0" lower="0.0" upper="0.548" velocity="0.5"/> -->
    <parent link="base_link"/>
    <child link="thruster_bot"/>
    <origin xyz="0 0 -2"/>
  </joint>
  <link name="thruster_bot_1">
    <visual>
      <geometry>
        <box size="0.2 0.2 0.2"/>
      </geometry>
      <origin rpy="0 0 0" xyz="0 0 0"/>
      <material name="green"/>
    </visual>
    <inertial>
      <mass value="0.001"/>
      <!-- <origin xyz="0 0 0"/> -->
      <inertia ixx="1e-3" ixy="0.0" ixz="0.0" iyy="1e-3" iyz="0.0" izz="1e-3"/>
    </inertial>
  </link>
  <!-- Prismatic joints with no effort so pinocchio recognizes
            them as controllable joints.
         -->
  <joint name="base_to_thruster_bot_1" type="fixed">
    <!-- <limit effort="1e-10" lower="0" upper="1e-10" velocity="1e-10"/> -->
    <!-- <axis xyz="${axis}"/> -->
    <!-- <limit effort="1000.0" lower="0.0" upper="0.548" velocity="0.5"/> -->
    <parent link="base_link"/>
    <child link="thruster_bot_1"/>
    <origin xyz="0 -1.3 -1.8"/>
  </joint>
  <link name="thruster_bot_2">
    <visual>
      <geometry>
        <box size="0.2 0.2 0.2"/>
      </geometry>
      <origin rpy="0 0 0" xyz="0 0 0"/>
      <material name="green"/>
    </visual>
    <inertial>
      <mass value="0.001"/>
      <!-- <origin xyz="0 0 0"/> -->
      <inertia ixx="1e-3" ixy="0.0" ixz="0.0" iyy="1e-3" iyz="0.0" izz="1e-3"/>
    </inertial>
  </link>
  <!-- Prismatic joints with no effort so pinocchio recognizes
            them as controllable joints.
         -->
  <joint name="base_to_thruster_bot_2" type="fixed">
    <!-- <limit effort="1e-10" lower="0" upper="1e-10" velocity="1e-10"/> -->
    <!-- <axis xyz="${axis}"/> -->
    <!-- <limit effort="1000.0" lower="0.0" upper="0.548" velocity="0.5"/> -->
    <parent link="base_link"/>
    <child link="thruster_bot_2"/>
    <origin xyz="-1.3 0 -1.8"/>
  </joint>
  <link name="thruster_bot_3">
    <visual>
      <geometry>
        <box size="0.2 0.2 0.2"/>
      </geometry>
      <origin rpy="0 0 0" xyz="0 0 0"/>
      <material name="green"/>
    </visual>
    <inertial>
      <mass value="0.001"/>
      <!-- <origin xyz="0 0 0"/> -->
      <inertia ixx="1e-3" ixy="0.0" ixz="0.0" iyy="1e-3" iyz="0.0" izz="1e-3"/>
    </inertial>
  </link>
  <!-- Prismatic joints with no effort so pinocchio recognizes
            them as controllable joints.
         -->
  <joint name="base_to_thruster_bot_3" type="fixed">
    <!-- <limit effort="1e-10" lower="0" upper="1e-10" velocity="1e-10"/> -->
    <!-- <axis xyz="${axis}"/> -->
    <!-- <limit effort="1000.0" lower="0.0" upper="0.548" velocity="0.5"/> -->
    <parent link="base_link"/>
    <child link="thruster_bot_3"/>
    <origin xyz="0 1.3 -1.8"/>
  </joint>
  <link name="thruster_bot_4">
    <visual>
      <geometry>
        <box size="0.2 0.2 0.2"/>
      </geometry>
      <origin rpy="0 0 0" xyz="0 0 0"/>
      <material name="green"/>
    </visual>
    <inertial>
      <mass value="0.001"/>
      <!-- <origin xyz="0 0 0"/> -->
      <inertia ixx="1e-3" ixy="0.0" ixz="0.0" iyy="1e-3" iyz="0.0" izz="1e-3"/>
    </inertial>
  </link>
  <!-- Prismatic joints with no effort so pinocchio recognizes
            them as controllable joints.
         -->
  <joint name="base_to_thruster_bot_4" type="fixed">
    <!-- <limit effort="1e-10" lower="0" upper="1e-10" velocity="1e-10"/> -->
    <!-- <axis xyz="${axis}"/> -->
    <!-- <limit effort="1000.0" lower="0.0" upper="0.548" velocity="0.5"/> -->
    <parent link="base_link"/>
    <child link="thruster_bot_4"/>
    <origin xyz="1.3 0 -1.8"/>
  </joint>
  <link name="thruster_top">
    <visual>
      <geometry>
        <box size="0.2 0.2 0.2"/>
      </geometry>
      <origin rpy="0 0 0" xyz="0 0 0"/>
      <material name="green"/>
    </visual>
    <inertial>
      <mass value="0.001"/>
      <!-- <origin xyz="0 0 0"/> -->
      <inertia ixx="1e-3" ixy="0.0" ixz="0.0" iyy="1e-3" iyz="0.0" izz="1e-3"/>
    </inertial>
  </link>
  <!-- Prismatic joints with no effort so pinocchio recognizes
            them as controllable joints.
         -->
  <joint name="base_to_thruster_top" type="fixed">
    <!-- <limit effort="1e-10" lower="0" upper="1e-10" velocity="1e-10"/> -->
    <!-- <axis xyz="${axis}"/> -->
    <!-- <limit effort="1000.0" lower="0.0" upper="0.548" velocity="0.5"/> -->
    <parent link="base_link"/>
    <child link="thruster_top"/>
    <origin xyz="0 0 2"/>
  </joint>
  <link name="thruster_top_1">
    <visual>
      <geometry>
        <box size="0.2 0.2 0.2"/>
      </geometry>
      <origin rpy="0 0 0" xyz="0 0 0"/>
      <material name="green"/>
    </visual>
    <inertial>
      <mass value="0.001"/>
      <!-- <origin xyz="0 0 0"/> -->
      <inertia ixx="1e-3" ixy="0.0" ixz="0.0" iyy="1e-3" iyz="0.0" izz="1e-3"/>
    </inertial>
  </link>
  <!-- Prismatic joints with no effort so pinocchio recognizes
            them as controllable joints.
         -->
  <joint name="base_to_thruster_top_1" type="fixed">
    <!-- <limit effort="1e-10" lower="0" upper="1e-10" velocity="1e-10"/> -->
    <!-- <axis xyz="${axis}"/> -->
    <!-- <limit effort="1000.0" lower="0.0" upper="0.548" velocity="0.5"/> -->
    <parent link="base_link"/>
    <child link="thruster_top_1"/>
    <origin xyz="0 -1.3 1.8"/>
  </joint>
  <link name="thruster_top_2">
    <visual>
      <geometry>
        <box size="0.2 0.2 0.2"/>
      </geometry>
      <origin rpy="0 0 0" xyz="0 0 0"/>
      <material name="green"/>
    </visual>
    <inertial>
      <mass value="0.001"/>
      <!-- <origin xyz="0 0 0"/> -->
      <inertia ixx="1e-3" ixy="0.0" ixz="0.0" iyy="1e-3" iyz="0.0" izz="1e-3"/>
    </inertial>
  </link>
  <!-- Prismatic joints with no effort so pinocchio recognizes
            them as controllable joints.
         -->
  <joint name="base_to_thruster_top_2" type="fixed">
    <!-- <limit effort="1e-10" lower="0" upper="1e-10" velocity="1e-10"/> -->
    <!-- <axis xyz="${axis}"/> -->
    <!-- <limit effort="1000.0" lower="0.0" upper="0.548" velocity="0.5"/> -->
    <parent link="base_link"/>
    <child link="thruster_top_2"/>
    <origin xyz="-1.3 0 1.8"/>
  </joint>
  <link name="thruster_top_3">
    <visual>
      <geometry>
        <box size="0.2 0.2 0.2"/>
      </geometry>
      <origin rpy="0 0 0" xyz="0 0 0"/>
      <material name="green"/>
    </visual>
    <inertial>
      <mass value="0.001"/>
      <!-- <origin xyz="0 0 0"/> -->
      <inertia ixx="1e-3" ixy="0.0" ixz="0.0" iyy="1e-3" iyz="0.0" izz="1e-3"/>
    </inertial>
  </link>
  <!-- Prismatic joints with no effort so pinocchio recognizes
            them as controllable joints.
         -->
  <joint name="base_to_thruster_top_3" type="fixed">
    <!-- <limit effort="1e-10" lower="0" upper="1e-10" velocity="1e-10"/> -->
    <!-- <axis xyz="${axis}"/> -->
    <!-- <limit effort="1000.0" lower="0.0" upper="0.548" velocity="0.5"/> -->
    <parent link="base_link"/>
    <child link="thruster_top_3"/>
    <origin xyz="0 1.3 1.8"/>
  </joint>
  <link name="thruster_top_4">
    <visual>
      <geometry>
        <box size="0.2 0.2 0.2"/>
      </geometry>
      <origin rpy="0 0 0" xyz="0 0 0"/>
      <material name="green"/>
    </visual>
    <inertial>
      <mass value="0.001"/>
      <!-- <origin xyz="0 0 0"/> -->
      <inertia ixx="1e-3" ixy="0.0" ixz="0.0" iyy="1e-3" iyz="0.0" izz="1e-3"/>
    </inertial>
  </link>
  <!-- Prismatic joints with no effort so pinocchio recognizes
            them as controllable joints.
         -->
  <joint name="base_to_thruster_top_4" type="fixed">
    <!-- <limit effort="1e-10" lower="0" upper="1e-10" velocity="1e-10"/> -->
    <!-- <axis xyz="${axis}"/> -->
    <!-- <limit effort="1000.0" lower="0.0" upper="0.548" velocity="0.5"/> -->
    <parent link="base_link"/>
    <child link="thruster_top_4"/>
    <origin xyz="1.3 0 1.8"/>
  </joint>
  <!-- <xacro:thruster name="bot_2" origin="-1.3 -1 -1.8"/> -->
  <!-- <xacro:thruster name="bot_3" origin="1.3 -1 -1.8"/> -->
  <!-- <xacro:thruster name="bot_4" origin="1 -1.3 -1.8"/> -->
  <!-- <xacro:thruster name="bot_5" origin="1.3 1 -1.8"/> -->
  <!-- <xacro:thruster name="bot_6" origin="1 1.3 -1.8"/> -->
  <!-- <xacro:thruster name="bot_7" origin="-1 1.3 -1.8"/> -->
  <!-- <xacro:thruster name="bot_8" origin="-1.3 1 -1.8"/> -->
  <!-- <xacro:thruster name="top" origin="0 0 2"/> -->
  <!-- <xacro:thruster name="top_1" origin="-1 -1.3 1.8"/> -->
  <!-- <xacro:thruster name="top_2" origin="-1.3 -1 1.8"/> -->
  <!-- <xacro:thruster name="top_3" origin="1.3 -1 1.8"/> -->
  <!-- <xacro:thruster name="top_4" origin="1 -1.3 1.8"/> -->
  <!-- <xacro:thruster name="top_5" origin="1.3 1 1.8"/> -->
  <!-- <xacro:thruster name="top_6" origin="1 1.3 1.8"/> -->
  <!-- <xacro:thruster name="top_7" origin="-1 1.3 1.8"/> -->
  <!-- <xacro:thruster name="top_8" origin="-1.3 1 1.8"/> -->
  <!-- joints -->
  <joint name="base_to_front" type="fixed">
    <parent link="base_link"/>
    <child link="front"/>
    <origin xyz="0 0 2"/>
  </joint>
  <joint name="base_to_left_array" type="fixed">
    <parent link="base_link"/>
    <child link="left_array"/>
    <origin xyz="-1 -0.5 -1"/>
  </joint>
  <joint name="base_to_right_array" type="fixed">
    <parent link="base_link"/>
    <child link="right_array"/>
    <origin xyz="1 -0.5 -1"/>
  </joint>
  <joint name="base_to_top_array" type="fixed">
    <parent link="base_link"/>
    <child link="top_array"/>
    <origin xyz="0 1 -1"/>
  </joint>
  <joint name="base_to_bot_array" type="fixed">
    <parent link="base_link"/>
    <child link="bot_array"/>
    <origin xyz="0 -1 -1"/>
  </joint>
  <!-- arm -->
  <link name="arm_one">
    <visual>
      <geometry>
        <cylinder length="0.5" radius="0.1"/>
      </geometry>
      <origin rpy="0 0 0" xyz="0 0 0"/>
      <material name="white"/>
    </visual>
    <inertial>
      <mass value="0"/>
      <origin xyz="0 0 0"/>
      <inertia ixx="0" ixy="0.0" ixz="0.0" iyy="0" iyz="0.0" izz="0"/>
    </inertial>
  </link>
  <link name="arm_two">
    <visual>
      <geometry>
        <cylinder length="2" radius="0.1"/>
      </geometry>
      <origin rpy="0 0 0" xyz="0 0 1"/>
      <material name="white"/>
    </visual>
    <inertial>
      <mass value="10"/>
      <origin xyz="0 0 0"/>
      <inertia ixx="13.3333333333" ixy="0.0" ixz="0.0" iyy="0" iyz="0.0" izz="13.3333333333"/>
    </inertial>
  </link>
  <link name="arm_three">
    <visual>
      <geometry>
        <cylinder length="2" radius="0.1"/>
      </geometry>
      <origin rpy="0 0 0" xyz="0.2 0 -1"/>
      <material name="white"/>
    </visual>
    <inertial>
      <mass value="10"/>
      <origin xyz="0 0 0"/>
      <inertia ixx="13.3333333333" ixy="0.0" ixz="0.0" iyy="0" iyz="0.0" izz="13.3333333333"/>
    </inertial>
  </link>
  <joint name="base_to_arm" type="revolute">
    <parent link="base_link"/>
    <child link="arm_one"/>
    <limit effort="100.0" lower="-1.57" upper="1.57" velocity="0.5"/>
    <axis xyz="1 0 0"/>
    <origin xyz="1.5 0 -0.25"/>
  </joint>
  <joint name="arm_one_to_two" type="revolute">
    <parent link="arm_one"/>
    <child link="arm_two"/>
    <limit effort="100.0" lower="0" upper="3.14" velocity="0.5"/>
    <axis xyz="0 1 0"/>
    <origin xyz="0 0 0"/>
  </joint>
  <joint name="arm_two_to_three" type="revolute">
    <parent link="arm_two"/>
    <child link="arm_three"/>
    <limit effort="100.0" lower="-1.57" upper="1.57" velocity="0.5"/>
    <axis xyz="0 1 0"/>
    <origin xyz="0 0 2"/>
  </joint>
</robot>

